Workbook

Sheet Category
A1: ID | B1: CategoryName | C1: Description
A2: 1 | B2: Beverages | C2: Soft drinks, coffees, teas, beers, and ales
A3: 2 | B3: Condiments | C3: Sweet and savory sauces, relishes, spreads, and seasonings
A4: 3 | B4: Confections | C4: Desserts, candies, and sweet breads
A5: 4 | B5: Dairy Products | C5: Cheeses
A6: 5 | B6: Grains/Cereals | C6: Breads, crackers, pasta, and cereal
A7: 6 | B7: Meat/Poultry | C7: Prepared meats
A8: 7 | B8: Produce | C8: Dried fruit and bean curd
A9: 8 | B9: Seafood | C9: Seaweed and fish

Sheet Orders
A1: OrderID | B1: CustomerID | C1: OrderDate
A2: 10248 | B2: VINET | C2: 35250
A3: 10249 | B3: TOMSP | C3: 35251
A4: 10250 | B4: HANAR | C4: 35254
A5: 10251 | B5: VICTE | C5: 35254
A6: 10252 | B6: SUPRD | C6: 35255
A7: 10253 | B7: HANAR | C7: 35256
A8: 10254 | B8: CHOPS | C8: 35257
A9: 10255 | B9: RICSU | C9: 35258
A10: 10256 | B10: WELLI | C10: 35261
A11: 10257 | B11: HILAA | C11: 35262
A12: 10258 | B12: ERNSH | C12: 35263
A13: 10259 | B13: CENTC | C13: 35264
... A831: 11077 | B831: RATTC | C831: 35921

Sheet Product
A1: ProductID | B1: ProductName | C1: SupplierID | D1: CategoryID | E1: QuantityPerUnit | F1: UnitPrice | G1: CategoryName
A2: 1 | B2: Chai | C2: 1 | D2: 1 | E2: 10 boxes x 20 bags | F2: 18 | G2: =_xlfn.XLOOKUP(Products[[#This Row],[CategoryID]],Category!A:A,Category!B:B,"Not Found") -> Beverages
A3: 2 | B3: Chang | C3: 1 | D3: 1 | E3: 24 - 12 oz bottles | F3: 19 | G3: =_xlfn.XLOOKUP(Products[[#This Row],[CategoryID]],Category!A:A,Category!B:B,"Not Found") -> Beverages
A4: 3 | B4: Aniseed Syrup | C4: 1 | D4: 2 | E4: 12 - 550 ml bottles | F4: 10 | G4: =_xlfn.XLOOKUP(Products[[#This Row],[CategoryID]],Category!A:A,Category!B:B,"Not Found") -> Condiments
A5: 4 | B5: Chef Anton's Cajun Seasoning | C5: 2 | D5: 2 | E5: 48 - 6 oz jars | F5: 22 | G5: =_xlfn.XLOOKUP(Products[[#This Row],[CategoryID]],Category!A:A,Category!B:B,"Not Found") -> Condiments
A6: 5 | B6: Chef Anton's Gumbo Mix | C6: 2 | D6: 2 | E6: 36 boxes | F6: 21.35 | G6: =_xlfn.XLOOKUP(Products[[#This Row],[CategoryID]],Category!A:A,Category!B:B,"Not Found") -> Condiments
A7: 6 | B7: Grandma's Boysenberry Spread | C7: 3 | D7: 2 | E7: 12 - 8 oz jars | F7: 25 | G7: =_xlfn.XLOOKUP(Products[[#This Row],[CategoryID]],Category!A:A,Category!B:B,"Not Found") -> Condiments
A8: 7 | B8: Uncle Bob's Organic Dried Pears | C8: 3 | D8: 7 | E8: 12 - 1 lb pkgs. | F8: 30 | G8: =_xlfn.XLOOKUP(Products[[#This Row],[CategoryID]],Category!A:A,Category!B:B,"Not Found") -> Produce
A9: 8 | B9: Northwoods Cranberry Sauce | C9: 3 | D9: 2 | E9: 12 - 12 oz jars | F9: 40 | G9: =_xlfn.XLOOKUP(Products[[#This Row],[CategoryID]],Category!A:A,Category!B:B,"Not Found") -> Condiments
A10: 9 | B10: Mishi Kobe Niku | C10: 4 | D10: 6 | E10: 18 - 500 g pkgs. | F10: 97 | G10: =_xlfn.XLOOKUP(Products[[#This Row],[CategoryID]],Category!A:A,Category!B:B,"Not Found") -> Meat/Poultry
A11: 10 | B11: Ikura | C11: 4 | D11: 8 | E11: 12 - 200 ml jars | F11: 31 | G11: =_xlfn.XLOOKUP(Products[[#This Row],[CategoryID]],Category!A:A,Category!B:B,"Not Found") -> Seafood
A12: 11 | B12: Queso Cabrales | C12: 5 | D12: 4 | E12: 1 kg pkg. | F12: 21 | G12: =_xlfn.XLOOKUP(Products[[#This Row],[CategoryID]],Category!A:A,Category!B:B,"Not Found") -> Dairy Products
A13: 12 | B13: Queso Manchego La Pastora | C13: 5 | D13: 4 | E13: 10 - 500 g pkgs. | F13: 38 | G13: =_xlfn.XLOOKUP(Products[[#This Row],[CategoryID]],Category!A:A,Category!B:B,"Not Found") -> Dairy Products
... A78: 77 | B78: Original Frankfurter grüne Soße | C78: 12 | D78: 2 | E78: 12 boxes | F78: 13 | G78: =_xlfn.XLOOKUP(Products[[#This Row],[CategoryID]],Category!A:A,Category!B:B,"Not Found") -> Condiments

Sheet OrderDetails
A1: OrderID | B1: ProductID | C1: UnitPrice | D1: Quantity | E1: Discount | F1: CustomerID | G1: OrderDate | H1: Sales Amount | I1: CategoryName | J1: Season | K1: ProductName | N1: Question: Why is the product price in the OrderDetails table not the same as the product price in the Product table? Answer: The difference between the product price in the OrderDetails table and the Product table exists because these two tables represent different types of pricing information. The Product table contains the base or catalog price of each product, which is defined as a reference and relatively stable value. In contrast, the OrderDetails table stores the actual transaction price recorded at the time each order is placed. This price may differ from the base price due to various factors such as periodic price changes, market conditions, specific agreements with customers, or sales policies. Therefore, the UnitPrice in the OrderDetails table is a dynamic value that reflects real transaction conditions, while the UnitPrice in the Product table is considered a standard reference price. | Q1: سوال: چرا قیمت محصول در جدول OrderDetails با قیمت محصول در جدول Product یکسان نیست؟ پاسخ: اختلاف بین قیمت محصول در جدول OrderDetails و جدول Product به این دلیل است که این دو جدول دو نوع متفاوت از اطلاعات قیمت‌گذاری را نمایش می‌دهند. جدول Product شامل قیمت پایه یا کاتالوگی هر محصول است که به‌عنوان یک مقدار مرجع و نسبتاً ثابت تعریف می‌شود، در حالی که جدول OrderDetails قیمت واقعی ثبت‌شده در زمان انجام هر سفارش را ذخیره می‌کند. این قیمت ممکن است در زمان خرید به دلایل مختلفی مانند تغییرات دوره‌ای قیمت، شرایط بازار، قراردادهای خاص با مشتریان یا سیاست‌های فروش متفاوت از قیمت پایه باشد. بنابراین، UnitPrice در OrderDetails یک مقدار پویا و وابسته به زمان و شرایط واقعی تراکنش است، در حالی که UnitPrice در Product یک مقدار استاندارد و مرجع محسوب می‌شود.
A2: 10248 | B2: 11 | C2: 14 | D2: 12 | E2: 0 | F2: =_xlfn.XLOOKUP(A2,Orders!A:A,Orders!B:B,"not found") -> VINET | G2: =_xlfn.XLOOKUP(OrderDetails[[#This Row],[OrderID]],Orders!A:A,Orders!C:C,"Not Found") -> 35250 | H2: =(OrderDetails[[#This Row],[UnitPrice]]*OrderDetails[[#This Row],[Quantity]])*(1-OrderDetails[[#This Row],[Discount]]) -> 168 | I2: =_xlfn.XLOOKUP(OrderDetails[[#This Row],[ProductID]],Product!A:A,Product!G:G,"Not Found") -> Dairy Products | J2: =LOOKUP(MONTH(G2),{1,4,7,10},{"Winter","Spring","Summer","Autumn"}) -> Summer | K2: =_xlfn.XLOOKUP(OrderDetails[[#This Row],[ProductID]],Product!A:A,Product!B:B,"Not Found") -> Queso Cabrales
A3: 10248 | B3: 42 | C3: 9.8 | D3: 10 | E3: 0 | F3: =_xlfn.XLOOKUP(A3,Orders!A:A,Orders!B:B,"not found") -> VINET | G3: =_xlfn.XLOOKUP(OrderDetails[[#This Row],[OrderID]],Orders!A:A,Orders!C:C,"Not Found") -> 35250 | H3: =(OrderDetails[[#This Row],[UnitPrice]]*OrderDetails[[#This Row],[Quantity]])*(1-OrderDetails[[#This Row],[Discount]]) -> 98 | I3: =_xlfn.XLOOKUP(OrderDetails[[#This Row],[ProductID]],Product!A:A,Product!G:G,"Not Found") -> Grains/Cereals | J3: =LOOKUP(MONTH(G3),{1,4,7,10},{"Winter","Spring","Summer","Autumn"}) -> Summer | K3: =_xlfn.XLOOKUP(OrderDetails[[#This Row],[ProductID]],Product!A:A,Product!B:B,"Not Found") -> Singaporean Hokkien Fried Mee
A4: 10248 | B4: 72 | C4: 34.8 | D4: 5 | E4: 0 | F4: =_xlfn.XLOOKUP(A4,Orders!A:A,Orders!B:B,"not found") -> VINET | G4: =_xlfn.XLOOKUP(OrderDetails[[#This Row],[OrderID]],Orders!A:A,Orders!C:C,"Not Found") -> 35250 | H4: =(OrderDetails[[#This Row],[UnitPrice]]*OrderDetails[[#This Row],[Quantity]])*(1-OrderDetails[[#This Row],[Discount]]) -> 174 | I4: =_xlfn.XLOOKUP(OrderDetails[[#This Row],[ProductID]],Product!A:A,Product!G:G,"Not Found") -> Dairy Products | J4: =LOOKUP(MONTH(G4),{1,4,7,10},{"Winter","Spring","Summer","Autumn"}) -> Summer | K4: =_xlfn.XLOOKUP(OrderDetails[[#This Row],[ProductID]],Product!A:A,Product!B:B,"Not Found") -> Mozzarella di Giovanni
A5: 10249 | B5: 14 | C5: 18.6 | D5: 9 | E5: 0 | F5: =_xlfn.XLOOKUP(A5,Orders!A:A,Orders!B:B,"not found") -> TOMSP | G5: =_xlfn.XLOOKUP(OrderDetails[[#This Row],[OrderID]],Orders!A:A,Orders!C:C,"Not Found") -> 35251 | H5: =(OrderDetails[[#This Row],[UnitPrice]]*OrderDetails[[#This Row],[Quantity]])*(1-OrderDetails[[#This Row],[Discount]]) -> 167.4 | I5: =_xlfn.XLOOKUP(OrderDetails[[#This Row],[ProductID]],Product!A:A,Product!G:G,"Not Found") -> Produce | J5: =LOOKUP(MONTH(G5),{1,4,7,10},{"Winter","Spring","Summer","Autumn"}) -> Summer | K5: =_xlfn.XLOOKUP(OrderDetails[[#This Row],[ProductID]],Product!A:A,Product!B:B,"Not Found") -> Tofu
A6: 10249 | B6: 51 | C6: 42.4 | D6: 40 | E6: 0 | F6: =_xlfn.XLOOKUP(A6,Orders!A:A,Orders!B:B,"not found") -> TOMSP | G6: =_xlfn.XLOOKUP(OrderDetails[[#This Row],[OrderID]],Orders!A:A,Orders!C:C,"Not Found") -> 35251 | H6: =(OrderDetails[[#This Row],[UnitPrice]]*OrderDetails[[#This Row],[Quantity]])*(1-OrderDetails[[#This Row],[Discount]]) -> 1696 | I6: =_xlfn.XLOOKUP(OrderDetails[[#This Row],[ProductID]],Product!A:A,Product!G:G,"Not Found") -> Produce | J6: =LOOKUP(MONTH(G6),{1,4,7,10},{"Winter","Spring","Summer","Autumn"}) -> Summer | K6: =_xlfn.XLOOKUP(OrderDetails[[#This Row],[ProductID]],Product!A:A,Product!B:B,"Not Found") -> Manjimup Dried Apples
A7: 10250 | B7: 41 | C7: 7.7 | D7: 10 | E7: 0 | F7: =_xlfn.XLOOKUP(A7,Orders!A:A,Orders!B:B,"not found") -> HANAR | G7: =_xlfn.XLOOKUP(OrderDetails[[#This Row],[OrderID]],Orders!A:A,Orders!C:C,"Not Found") -> 35254 | H7: =(OrderDetails[[#This Row],[UnitPrice]]*OrderDetails[[#This Row],[Quantity]])*(1-OrderDetails[[#This Row],[Discount]]) -> 77 | I7: =_xlfn.XLOOKUP(OrderDetails[[#This Row],[ProductID]],Product!A:A,Product!G:G,"Not Found") -> Seafood | J7: =LOOKUP(MONTH(G7),{1,4,7,10},{"Winter","Spring","Summer","Autumn"}) -> Summer | K7: =_xlfn.XLOOKUP(OrderDetails[[#This Row],[ProductID]],Product!A:A,Product!B:B,"Not Found") -> Jack's New England Clam Chowder
A8: 10250 | B8: 51 | C8: 42.4 | D8: 35 | E8: 0.15000001 | F8: =_xlfn.XLOOKUP(A8,Orders!A:A,Orders!B:B,"not found") -> HANAR | G8: =_xlfn.XLOOKUP(OrderDetails[[#This Row],[OrderID]],Orders!A:A,Orders!C:C,"Not Found") -> 35254 | H8: =(OrderDetails[[#This Row],[UnitPrice]]*OrderDetails[[#This Row],[Quantity]])*(1-OrderDetails[[#This Row],[Discount]]) -> 1261.4 | I8: =_xlfn.XLOOKUP(OrderDetails[[#This Row],[ProductID]],Product!A:A,Product!G:G,"Not Found") -> Produce | J8: =LOOKUP(MONTH(G8),{1,4,7,10},{"Winter","Spring","Summer","Autumn"}) -> Summer | K8: =_xlfn.XLOOKUP(OrderDetails[[#This Row],[ProductID]],Product!A:A,Product!B:B,"Not Found") -> Manjimup Dried Apples
A9: 10250 | B9: 65 | C9: 16.8 | D9: 15 | E9: 0.15000001 | F9: =_xlfn.XLOOKUP(A9,Orders!A:A,Orders!B:B,"not found") -> HANAR | G9: =_xlfn.XLOOKUP(OrderDetails[[#This Row],[OrderID]],Orders!A:A,Orders!C:C,"Not Found") -> 35254 | H9: =(OrderDetails[[#This Row],[UnitPrice]]*OrderDetails[[#This Row],[Quantity]])*(1-OrderDetails[[#This Row],[Discount]]) -> 214.2 | I9: =_xlfn.XLOOKUP(OrderDetails[[#This Row],[ProductID]],Product!A:A,Product!G:G,"Not Found") -> Condiments | J9: =LOOKUP(MONTH(G9),{1,4,7,10},{"Winter","Spring","Summer","Autumn"}) -> Summer | K9: =_xlfn.XLOOKUP(OrderDetails[[#This Row],[ProductID]],Product!A:A,Product!B:B,"Not Found") -> Louisiana Fiery Hot Pepper Sauce
A10: 10251 | B10: 22 | C10: 16.8 | D10: 6 | E10: 0.050000001 | F10: =_xlfn.XLOOKUP(A10,Orders!A:A,Orders!B:B,"not found") -> VICTE | G10: =_xlfn.XLOOKUP(OrderDetails[[#This Row],[OrderID]],Orders!A:A,Orders!C:C,"Not Found") -> 35254 | H10: =(OrderDetails[[#This Row],[UnitPrice]]*OrderDetails[[#This Row],[Quantity]])*(1-OrderDetails[[#This Row],[Discount]]) -> 95.76 | I10: =_xlfn.XLOOKUP(OrderDetails[[#This Row],[ProductID]],Product!A:A,Product!G:G,"Not Found") -> Grains/Cereals | J10: =LOOKUP(MONTH(G10),{1,4,7,10},{"Winter","Spring","Summer","Autumn"}) -> Summer | K10: =_xlfn.XLOOKUP(OrderDetails[[#This Row],[ProductID]],Product!A:A,Product!B:B,"Not Found") -> Gustaf's Knäckebröd
A11: 10251 | B11: 57 | C11: 15.6 | D11: 15 | E11: 0.050000001 | F11: =_xlfn.XLOOKUP(A11,Orders!A:A,Orders!B:B,"not found") -> VICTE | G11: =_xlfn.XLOOKUP(OrderDetails[[#This Row],[OrderID]],Orders!A:A,Orders!C:C,"Not Found") -> 35254 | H11: =(OrderDetails[[#This Row],[UnitPrice]]*OrderDetails[[#This Row],[Quantity]])*(1-OrderDetails[[#This Row],[Discount]]) -> 222.3 | I11: =_xlfn.XLOOKUP(OrderDetails[[#This Row],[ProductID]],Product!A:A,Product!G:G,"Not Found") -> Grains/Cereals | J11: =LOOKUP(MONTH(G11),{1,4,7,10},{"Winter","Spring","Summer","Autumn"}) -> Summer | K11: =_xlfn.XLOOKUP(OrderDetails[[#This Row],[ProductID]],Product!A:A,Product!B:B,"Not Found") -> Ravioli Angelo
A12: 10251 | B12: 65 | C12: 16.8 | D12: 20 | E12: 0 | F12: =_xlfn.XLOOKUP(A12,Orders!A:A,Orders!B:B,"not found") -> VICTE | G12: =_xlfn.XLOOKUP(OrderDetails[[#This Row],[OrderID]],Orders!A:A,Orders!C:C,"Not Found") -> 35254 | H12: =(OrderDetails[[#This Row],[UnitPrice]]*OrderDetails[[#This Row],[Quantity]])*(1-OrderDetails[[#This Row],[Discount]]) -> 336 | I12: =_xlfn.XLOOKUP(OrderDetails[[#This Row],[ProductID]],Product!A:A,Product!G:G,"Not Found") -> Condiments | J12: =LOOKUP(MONTH(G12),{1,4,7,10},{"Winter","Spring","Summer","Autumn"}) -> Summer | K12: =_xlfn.XLOOKUP(OrderDetails[[#This Row],[ProductID]],Product!A:A,Product!B:B,"Not Found") -> Louisiana Fiery Hot Pepper Sauce
A13: 10252 | B13: 20 | C13: 64.8 | D13: 40 | E13: 0.050000001 | F13: =_xlfn.XLOOKUP(A13,Orders!A:A,Orders!B:B,"not found") -> SUPRD | G13: =_xlfn.XLOOKUP(OrderDetails[[#This Row],[OrderID]],Orders!A:A,Orders!C:C,"Not Found") -> 35255 | H13: =(OrderDetails[[#This Row],[UnitPrice]]*OrderDetails[[#This Row],[Quantity]])*(1-OrderDetails[[#This Row],[Discount]]) -> 2462.4 | I13: =_xlfn.XLOOKUP(OrderDetails[[#This Row],[ProductID]],Product!A:A,Product!G:G,"Not Found") -> Confections | J13: =LOOKUP(MONTH(G13),{1,4,7,10},{"Winter","Spring","Summer","Autumn"}) -> Summer | K13: =_xlfn.XLOOKUP(OrderDetails[[#This Row],[ProductID]],Product!A:A,Product!B:B,"Not Found") -> Sir Rodney's Marmalade
... A2156: 11077 | B2156: 77 | C2156: 13 | D2156: 2 | E2156: 0 | F2156: =_xlfn.XLOOKUP(A2156,Orders!A:A,Orders!B:B,"not found") -> RATTC | G2156: =_xlfn.XLOOKUP(OrderDetails[[#This Row],[OrderID]],Orders!A:A,Orders!C:C,"Not Found") -> 35921 | H2156: =(OrderDetails[[#This Row],[UnitPrice]]*OrderDetails[[#This Row],[Quantity]])*(1-OrderDetails[[#This Row],[Discount]]) -> 26 | I2156: =_xlfn.XLOOKUP(OrderDetails[[#This Row],[ProductID]],Product!A:A,Product!G:G,"Not Found") -> Condiments | J2156: =LOOKUP(MONTH(G2156),{1,4,7,10},{"Winter","Spring","Summer","Autumn"}) -> Spring | K2156: =_xlfn.XLOOKUP(OrderDetails[[#This Row],[ProductID]],Product!A:A,Product!B:B,"Not Found") -> Original Frankfurter grüne Soße

Sheet Sales Performance Overview
A1: Years and Season | B1: Total Sales | H1: Years and Month | I1: Total Sales %
A2: 1996 | H2: 1996
A3: Autumn | B3: 128355.4 | H3: Jul | I3: 0.13389736
A4: Summer | B4: 79728.57 | H4: Aug | I4: 0.12247592
A5: 1997 | H5: Sep | I5: 0.12678247
A6: Autumn | B6: 181681.46 | H6: Oct | I6: 0.18029128
A7: Spring | B7: 143177.04 | H7: Nov | I7: 0.21914252
A8: Summer | B8: 153937.77 | H8: Dec | I8: 0.21741045
A9: Winter | B9: 138288.92 | H9: 1997
A10: 1998 | H10: Jan | I10: 0.099270035
A11: Spring | B11: 142132.31 | H11: Feb | I11: 0.062363568
A12: Winter | B12: 298491.55 | H12: Mar | I12: 0.062466609
A13: Grand Total | B13: 1265793 | H13: Apr | I13: 0.085941053
H14: May | I14: 0.087153751
H15: Jun | I15: 0.058926713
H16: Jul | I16: 0.08268041
H17: Aug | I17: 0.076630698
H18: Sep | I18: 0.090148398
H19: Oct | I19: 0.10816857
H20: Nov | I20: 0.070547485
H21: Dec | I21: 0.11570271
H22: 1998
H23: Jan | I23: 0.21383796
H24: Feb | I24: 0.22562393
H25: Mar | I25: 0.23796749
H26: Apr | I26: 0.28096227
H27: May | I27: 0.041608346
H28: Grand Total | I28: 1

Sheet Sales Key Insights
A1: ProductName | B1: Sum of Sales Amount | H1: Row Labels | I1: Sum of Sales Amount2 | L1: CustomerID | M1: Count of OrderID | N1: Sum of Sales Amount
A2: Côte de Blaye | B2: 141396.73 | H2: Beverages | I2: 0.21162084 | L2: ALFKI | M2: 12 | N2: 4273
A3: Thüringer Rostbratwurst | B3: 80368.672 | H3: Condiments | I3: 0.083779166 | L3: ANATR | M3: 10 | N3: 1402.95
A4: Raclette Courdavault | B4: 71155.7 | H4: Confections | I4: 0.13221531 | L4: ANTON | M4: 17 | N4: 7023.9775
A5: Tarte au sucre | B5: 47234.97 | H5: Dairy Products | I5: 0.18526511 | L5: AROUT | M5: 30 | N5: 13390.65
A6: Camembert Pierrot | B6: 46825.48 | H6: Grains/Cereals | I6: 0.075640002 | L6: BERGS | M6: 52 | N6: 24927.577
A7: Gnocchi di nonna Alice | B7: 42593.06 | H7: Meat/Poultry | I7: 0.12879069 | L7: BLAUS | M7: 14 | N7: 3239.8
A8: Manjimup Dried Apples | B8: 41819.65 | H8: Produce | I8: 0.078989674 | L8: BLONP | M8: 26 | N8: 18534.08
A9: Alice Mutton | B9: 32698.38 | H9: Seafood | I9: 0.10369921 | L9: BOLID | M9: 6 | N9: 4232.85
A10: Carnarvon Tigers | B10: 29171.875 | H10: Grand Total | I10: 1 | L10: BONAP | M10: 44 | N10: 21963.252
A11: Rössle Sauerkraut | B11: 25696.64 | L11: BOTTM | M11: 35 | N11: 20801.6
A12: Mozzarella di Giovanni | B12: 24900.13 | L12: BSBEV | M12: 22 | N12: 6089.9
A13: Ipoh Coffee | B13: 23526.7 | L13: CACTU | M13: 11 | N13: 1814.8
A14: Sir Rodney's Marmalade | B14: 22563.36 | L14: CENTC | M14: 2 | N14: 100.8
A15: Uncle Bob's Organic Dried Pears | B15: 22044.3 | L15: CHOPS | M15: 22 | N15: 12348.88
A16: Wimmers gute Semmelknödel | B16: 21957.967 | L16: COMMI | M16: 10 | N16: 3810.75
A17: Gudbrandsdalsost | B17: 21942.36 | L17: CONSH | M17: 7 | N17: 1719.1
A18: Ikura | B18: 20867.34 | L18: DRACD | M18: 10 | N18: 3763.21
A19: Perth Pasties | B19: 20574.17 | L19: DUMON | M19: 9 | N19: 1615.9
A20: Gumbär Gummibärchen | B20: 19849.144 | L20: EASTC | M20: 21 | N20: 14761.035
A21: Flotemysost | B21: 19551.025 | L21: ERNSH | M21: 102 | N21: 104874.98
A22: Boston Crab Meat | B22: 17910.63 | L22: FAMIA | M22: 19 | N22: 4107.55
... A79: Grand Total | B79: 1265793 | L79: TORTU | M79: 29 | N79: 10812.15
L80: TRADH | M80: 13 | N80: 6850.664
L81: TRAIH | M81: 9 | N81: 1571.2
L82: VAFFE | M82: 31 | N82: 15843.925
L83: VICTE | M83: 25 | N83: 9182.43
L84: VINET | M84: 10 | N84: 1480
L85: WANDK | M85: 26 | N85: 9588.425
L86: WARTH | M86: 37 | N86: 15648.702
L87: WELLI | M87: 19 | N87: 6068.2
L88: WHITC | M88: 40 | N88: 27363.605
L89: WILMK | M89: 17 | N89: 3161.35
L90: WOLZA | M90: 16 | N90: 3531.95

Sheet Sales Composition Analysis
A1: ProductName | B1: Sum of Sales Amount2 | D1: Season / ProductName | E1: Sum of Sales Amount | G1: ProductName / Month | H1: Sum of Sales Amount
A2: Beverages | D2: Alice Mutton | G2: Alice Mutton
A3: Chai | B3: 0.010102836 | D3: Autumn | E3: 0.30726843 | G3: Jan | H3: 0.12929081
A4: Chang | B4: 0.012921512 | D4: Spring | E4: 0.21969896 | G4: Feb | H4: 0.071801722
A5: Chartreuse verte | B5: 0.0097129148 | D5: Summer | E5: 0.23973665 | G5: Mar | H5: 0.03220343
A6: Côte de Blaye | B6: 0.11170605 | D6: Winter | E6: 0.23329596 | G6: Apr | H6: 0.014312636
A7: Guaraná Fantástica | B7: 0.003558532 | D7: Alice Mutton Total | E7: 0.025832327 | G7: May | H7: 0.16578803
A8: Ipoh Coffee | B8: 0.01858653 | D8: Aniseed Syrup | G8: Jun | H8: 0.039598292
A9: Lakkalikööri | B9: 0.01245104 | D9: Autumn | E9: 0.14454665 | G9: Jul | H9: 0.14789724
A10: Laughing Lumberjack Lager | B10: 0.0018935165 | D10: Spring | E10: 0.29237845 | G10: Aug | H10: 0.025047112
A11: Outback Lager | B11: 0.0084315916 | D11: Summer | E11: 0.12483574 | G11: Sep | H11: 0.0667923
A12: Rhönbräu Klosterbier | B12: 0.0064603689 | D12: Winter | E12: 0.43823916 | G12: Oct | H12: 0.14724124
A13: Sasquatch Ale | B13: 0.0050169339 | D13: Aniseed Syrup Total | E13: 0.0024048165 | G13: Nov | H13: 0.053576966
A14: Steeleye Stout | B14: 0.010779013 | D14: Boston Crab Meat | G14: Dec | H14: 0.10645023
A15: Beverages Total | B15: 0.21162084 | D15: Autumn | E15: 0.095742026 | G15: Alice Mutton Total | H15: 0.025832327
A16: Condiments | D16: Spring | E16: 0.16180335 | G16: Aniseed Syrup
A17: Aniseed Syrup | B17: 0.0024048165 | D17: Summer | E17: 0.39818923 | G17: Jan | H17: 0.39093298
A18: Chef Anton's Cajun Seasoning | B18: 0.0067688001 | D18: Winter | E18: 0.34426539 | G18: Mar | H18: 0.047306176
A19: Chef Anton's Gumbo Mix | B19: 0.0042243873 | D19: Boston Crab Meat Total | E19: 0.01414973 | G19: Apr | H19: 0.082128778
A20: Genen Shouyu | B20: 0.0014100449 | D20: Camembert Pierrot | G20: May | H20: 0.21024967
A21: Grandma's Boysenberry Spread | B21: 0.0056383625 | D21: Autumn | E21: 0.19360741 | G21: Jul | H21: 0.045992116
A22: Gula Malacca | B22: 0.0078337806 | D22: Spring | E22: 0.22641989 | G22: Aug | H22: 0.078843627
A23: Louisiana Fiery Hot Pepper Sauce | B23: 0.010957471 | D23: Summer | E23: 0.26905651 | G23: Oct | H23: 0.019710907
A24: Louisiana Hot Spiced Okra | B24: 0.0026726328 | D24: Winter | E24: 0.31091619 | G24: Nov | H24: 0.065703022
A25: Northwoods Cranberry Sauce | B25: 0.010090117 | D25: Camembert Pierrot Total | E25: 0.036992998 | G25: Dec | H25: 0.05913272
A26: Original Frankfurter grüne Soße | B26: 0.007245758 | D26: Carnarvon Tigers | G26: Aniseed Syrup Total | H26: 0.0024048165
A27: Sirop d'érable | B27: 0.01133882 | D27: Autumn | E27: 0.27380825 | G27: Boston Crab Meat
A28: Vegie-spread | B28: 0.013194175 | D28: Spring | E28: 0.17953937 | G28: Jan | H28: 0.14115137
A29: Condiments Total | B29: 0.083779166 | D29: Summer | E29: 0.30251741 | G29: Feb | H29: 0.12222909
A30: Confections | D30: Winter | E30: 0.24413498 | G30: Mar | H30: 0.080884927
A31: Chocolade | B31: 0.0010813083 | D31: Carnarvon Tigers Total | E31: 0.023046323 | G31: Apr | H31: 0.077049216
A32: Gumbär Gummibärchen | B32: 0.015681193 | D32: Chai | G32: May | H32: 0.031333348
A33: Maxilaku | B33: 0.0073034056 | D33: Autumn | E33: 0.20867056 | G33: Jun | H33: 0.05342079
A34: NuNuCa Nuß-Nougat-Creme | B34: 0.0029265448 | D34: Spring | E34: 0.25272714 | G34: Jul | H34: 0.084184644
A35: Pavlova | B35: 0.013600782 | D35: Summer | E35: 0.17517067 | G35: Aug | H35: 0.13468538
A36: Schoggi Schokolade | B36: 0.011929182 | D36: Winter | E36: 0.36343163 | G36: Sep | H36: 0.17931921
A37: Scottish Longbreads | B37: 0.0068842218 | D37: Chai Total | E37: 0.010102836 | G37: Nov | H37: 0.094714703
A38: Sir Rodney's Marmalade | B38: 0.017825473 | D38: Chang | G38: Dec | H38: 0.0010273229
A39: Sir Rodney's Scones | B39: 0.007192329 | D39: Autumn | E39: 0.20049022 | G39: Boston Crab Meat Total | H39: 0.01414973
A40: Tarte au sucre | B40: 0.037316503 | D40: Spring | E40: 0.25550625 | G40: Camembert Pierrot
...
